[2022-12-11 14:26:04,976] {taskinstance.py:1159} INFO - Dependencies all met for <TaskInstance: first_dag.sum_column_task scheduled__2022-12-11T14:25:00+00:00 [queued]>
[2022-12-11 14:26:04,991] {taskinstance.py:1159} INFO - Dependencies all met for <TaskInstance: first_dag.sum_column_task scheduled__2022-12-11T14:25:00+00:00 [queued]>
[2022-12-11 14:26:04,992] {taskinstance.py:1356} INFO - 
--------------------------------------------------------------------------------
[2022-12-11 14:26:04,993] {taskinstance.py:1357} INFO - Starting attempt 1 of 1
[2022-12-11 14:26:04,994] {taskinstance.py:1358} INFO - 
--------------------------------------------------------------------------------
[2022-12-11 14:26:05,014] {taskinstance.py:1377} INFO - Executing <Task(PythonOperator): sum_column_task> on 2022-12-11 14:25:00+00:00
[2022-12-11 14:26:05,020] {standard_task_runner.py:52} INFO - Started process 703 to run task
[2022-12-11 14:26:05,024] {standard_task_runner.py:79} INFO - Running: ['***', 'tasks', 'run', 'first_dag', 'sum_column_task', 'scheduled__2022-12-11T14:25:00+00:00', '--job-id', '451', '--raw', '--subdir', 'DAGS_FOLDER/first-dag.py', '--cfg-path', '/tmp/tmp_ri8x2il', '--error-file', '/tmp/tmp67vw9w6f']
[2022-12-11 14:26:05,028] {standard_task_runner.py:80} INFO - Job 451: Subtask sum_column_task
[2022-12-11 14:26:05,107] {task_command.py:369} INFO - Running <TaskInstance: first_dag.sum_column_task scheduled__2022-12-11T14:25:00+00:00 [running]> on host 7e39590a7807
[2022-12-11 14:26:05,203] {taskinstance.py:1571} INFO - Exporting the following env vars:
AIRFLOW_CTX_DAG_OWNER=***
AIRFLOW_CTX_DAG_ID=first_dag
AIRFLOW_CTX_TASK_ID=sum_column_task
AIRFLOW_CTX_EXECUTION_DATE=2022-12-11T14:25:00+00:00
AIRFLOW_CTX_TRY_NUMBER=1
AIRFLOW_CTX_DAG_RUN_ID=scheduled__2022-12-11T14:25:00+00:00
[2022-12-11 14:26:05,221] {taskinstance.py:1889} ERROR - Task failed with exception
Traceback (most recent call last):
  File "/home/airflow/.local/lib/python3.7/site-packages/airflow/operators/python.py", line 171, in execute
    return_value = self.execute_callable()
  File "/home/airflow/.local/lib/python3.7/site-packages/airflow/operators/python.py", line 189, in execute_callable
    return self.python_callable(*self.op_args, **self.op_kwargs)
  File "/opt/airflow/dags/first-dag.py", line 31, in sum_column_and_diff
    sum_columns = reduce(lambda a, b: (a[0] + b[0], a[1] + b[1]), prepare_lines)
  File "/opt/airflow/dags/first-dag.py", line 29, in <lambda>
    (int(x[0]), int(x[1].replace("\n", ""))),
ValueError: invalid literal for int() with base 10: 'None779'
[2022-12-11 14:26:05,238] {taskinstance.py:1400} INFO - Marking task as FAILED. dag_id=first_dag, task_id=sum_column_task, execution_date=20221211T142500, start_date=20221211T142604, end_date=20221211T142605
[2022-12-11 14:26:05,258] {standard_task_runner.py:97} ERROR - Failed to execute job 451 for task sum_column_task (invalid literal for int() with base 10: 'None779'; 703)
[2022-12-11 14:26:05,294] {local_task_job.py:156} INFO - Task exited with return code 1
[2022-12-11 14:26:05,348] {local_task_job.py:273} INFO - 0 downstream tasks scheduled from follow-on schedule check
