[2022-12-04 16:59:01,703] {taskinstance.py:1159} INFO - Dependencies all met for <TaskInstance: first_dag.generate_two_int_task manual__2022-12-04T16:58:58.057943+00:00 [queued]>
[2022-12-04 16:59:01,717] {taskinstance.py:1159} INFO - Dependencies all met for <TaskInstance: first_dag.generate_two_int_task manual__2022-12-04T16:58:58.057943+00:00 [queued]>
[2022-12-04 16:59:01,718] {taskinstance.py:1356} INFO - 
--------------------------------------------------------------------------------
[2022-12-04 16:59:01,719] {taskinstance.py:1357} INFO - Starting attempt 1 of 1
[2022-12-04 16:59:01,720] {taskinstance.py:1358} INFO - 
--------------------------------------------------------------------------------
[2022-12-04 16:59:01,741] {taskinstance.py:1377} INFO - Executing <Task(PythonOperator): generate_two_int_task> on 2022-12-04 16:58:58.057943+00:00
[2022-12-04 16:59:01,749] {standard_task_runner.py:52} INFO - Started process 1137 to run task
[2022-12-04 16:59:01,759] {standard_task_runner.py:79} INFO - Running: ['***', 'tasks', 'run', 'first_dag', 'generate_two_int_task', 'manual__2022-12-04T16:58:58.057943+00:00', '--job-id', '179', '--raw', '--subdir', 'DAGS_FOLDER/first-dag.py', '--cfg-path', '/tmp/tmpeum5c0m6', '--error-file', '/tmp/tmpfm_7k5sf']
[2022-12-04 16:59:01,762] {standard_task_runner.py:80} INFO - Job 179: Subtask generate_two_int_task
[2022-12-04 16:59:01,847] {task_command.py:369} INFO - Running <TaskInstance: first_dag.generate_two_int_task manual__2022-12-04T16:58:58.057943+00:00 [running]> on host fb90b48d1471
[2022-12-04 16:59:01,956] {taskinstance.py:1571} INFO - Exporting the following env vars:
AIRFLOW_CTX_DAG_OWNER=***
AIRFLOW_CTX_DAG_ID=first_dag
AIRFLOW_CTX_TASK_ID=generate_two_int_task
AIRFLOW_CTX_EXECUTION_DATE=2022-12-04T16:58:58.057943+00:00
AIRFLOW_CTX_TRY_NUMBER=1
AIRFLOW_CTX_DAG_RUN_ID=manual__2022-12-04T16:58:58.057943+00:00
[2022-12-04 16:59:02,075] {taskinstance.py:1889} ERROR - Task failed with exception
Traceback (most recent call last):
  File "/home/airflow/.local/lib/python3.7/site-packages/airflow/operators/python.py", line 171, in execute
    return_value = self.execute_callable()
  File "/home/airflow/.local/lib/python3.7/site-packages/airflow/operators/python.py", line 189, in execute_callable
    return self.python_callable(*self.op_args, **self.op_kwargs)
  File "/opt/airflow/dags/first-dag.py", line 18, in generate_two_number
    file.writelines(generated_numbers)
TypeError: write() argument must be str, not int
[2022-12-04 16:59:02,102] {taskinstance.py:1400} INFO - Marking task as FAILED. dag_id=first_dag, task_id=generate_two_int_task, execution_date=20221204T165858, start_date=20221204T165901, end_date=20221204T165902
[2022-12-04 16:59:02,123] {standard_task_runner.py:97} ERROR - Failed to execute job 179 for task generate_two_int_task (write() argument must be str, not int; 1137)
[2022-12-04 16:59:02,172] {local_task_job.py:156} INFO - Task exited with return code 1
[2022-12-04 16:59:02,224] {local_task_job.py:273} INFO - 0 downstream tasks scheduled from follow-on schedule check
