[2022-12-11 20:20:01,467] {taskinstance.py:1159} INFO - Dependencies all met for <TaskInstance: first_dag.insert_data manual__2022-12-11T20:19:04.887695+00:00 [queued]>
[2022-12-11 20:20:01,494] {taskinstance.py:1159} INFO - Dependencies all met for <TaskInstance: first_dag.insert_data manual__2022-12-11T20:19:04.887695+00:00 [queued]>
[2022-12-11 20:20:01,495] {taskinstance.py:1356} INFO - 
--------------------------------------------------------------------------------
[2022-12-11 20:20:01,496] {taskinstance.py:1357} INFO - Starting attempt 1 of 1
[2022-12-11 20:20:01,498] {taskinstance.py:1358} INFO - 
--------------------------------------------------------------------------------
[2022-12-11 20:20:01,552] {taskinstance.py:1377} INFO - Executing <Task(PythonOperator): insert_data> on 2022-12-11 20:19:04.887695+00:00
[2022-12-11 20:20:01,559] {standard_task_runner.py:52} INFO - Started process 5736 to run task
[2022-12-11 20:20:01,571] {standard_task_runner.py:79} INFO - Running: ['***', 'tasks', 'run', 'first_dag', 'insert_data', 'manual__2022-12-11T20:19:04.887695+00:00', '--job-id', '1372', '--raw', '--subdir', 'DAGS_FOLDER/first-dag.py', '--cfg-path', '/tmp/tmpw9h2pass', '--error-file', '/tmp/tmptask6vfn']
[2022-12-11 20:20:01,574] {standard_task_runner.py:80} INFO - Job 1372: Subtask insert_data
[2022-12-11 20:20:01,983] {task_command.py:369} INFO - Running <TaskInstance: first_dag.insert_data manual__2022-12-11T20:19:04.887695+00:00 [running]> on host 7e39590a7807
[2022-12-11 20:20:02,524] {taskinstance.py:1571} INFO - Exporting the following env vars:
AIRFLOW_CTX_DAG_OWNER=***
AIRFLOW_CTX_DAG_ID=first_dag
AIRFLOW_CTX_TASK_ID=insert_data
AIRFLOW_CTX_EXECUTION_DATE=2022-12-11T20:19:04.887695+00:00
AIRFLOW_CTX_TRY_NUMBER=1
AIRFLOW_CTX_DAG_RUN_ID=manual__2022-12-11T20:19:04.887695+00:00
[2022-12-11 20:20:02,534] {taskinstance.py:1889} ERROR - Task failed with exception
Traceback (most recent call last):
  File "/home/airflow/.local/lib/python3.7/site-packages/airflow/operators/python.py", line 171, in execute
    return_value = self.execute_callable()
  File "/home/airflow/.local/lib/python3.7/site-packages/airflow/operators/python.py", line 189, in execute_callable
    return self.python_callable(*self.op_args, **self.op_kwargs)
TypeError: insert_data_to_db() missing 1 required positional argument: 'line'
[2022-12-11 20:20:02,818] {taskinstance.py:1400} INFO - Marking task as FAILED. dag_id=first_dag, task_id=insert_data, execution_date=20221211T201904, start_date=20221211T202001, end_date=20221211T202002
[2022-12-11 20:20:02,852] {standard_task_runner.py:97} ERROR - Failed to execute job 1372 for task insert_data (insert_data_to_db() missing 1 required positional argument: 'line'; 5736)
[2022-12-11 20:20:02,865] {local_task_job.py:156} INFO - Task exited with return code 1
[2022-12-11 20:20:02,948] {local_task_job.py:273} INFO - 0 downstream tasks scheduled from follow-on schedule check
