[2022-12-11 14:20:00,994] {taskinstance.py:1159} INFO - Dependencies all met for <TaskInstance: first_dag.sum_column_task scheduled__2022-12-11T14:19:00+00:00 [queued]>
[2022-12-11 14:20:01,019] {taskinstance.py:1159} INFO - Dependencies all met for <TaskInstance: first_dag.sum_column_task scheduled__2022-12-11T14:19:00+00:00 [queued]>
[2022-12-11 14:20:01,020] {taskinstance.py:1356} INFO - 
--------------------------------------------------------------------------------
[2022-12-11 14:20:01,022] {taskinstance.py:1357} INFO - Starting attempt 1 of 1
[2022-12-11 14:20:01,025] {taskinstance.py:1358} INFO - 
--------------------------------------------------------------------------------
[2022-12-11 14:20:01,059] {taskinstance.py:1377} INFO - Executing <Task(PythonOperator): sum_column_task> on 2022-12-11 14:19:00+00:00
[2022-12-11 14:20:01,072] {standard_task_runner.py:52} INFO - Started process 571 to run task
[2022-12-11 14:20:01,103] {standard_task_runner.py:79} INFO - Running: ['***', 'tasks', 'run', 'first_dag', 'sum_column_task', 'scheduled__2022-12-11T14:19:00+00:00', '--job-id', '418', '--raw', '--subdir', 'DAGS_FOLDER/first-dag.py', '--cfg-path', '/tmp/tmp5hmqpgvq', '--error-file', '/tmp/tmpenasg4l3']
[2022-12-11 14:20:01,106] {standard_task_runner.py:80} INFO - Job 418: Subtask sum_column_task
[2022-12-11 14:20:01,314] {task_command.py:369} INFO - Running <TaskInstance: first_dag.sum_column_task scheduled__2022-12-11T14:19:00+00:00 [running]> on host 7e39590a7807
[2022-12-11 14:20:01,499] {taskinstance.py:1571} INFO - Exporting the following env vars:
AIRFLOW_CTX_DAG_OWNER=***
AIRFLOW_CTX_DAG_ID=first_dag
AIRFLOW_CTX_TASK_ID=sum_column_task
AIRFLOW_CTX_EXECUTION_DATE=2022-12-11T14:19:00+00:00
AIRFLOW_CTX_TRY_NUMBER=1
AIRFLOW_CTX_DAG_RUN_ID=scheduled__2022-12-11T14:19:00+00:00
[2022-12-11 14:20:01,508] {taskinstance.py:1889} ERROR - Task failed with exception
Traceback (most recent call last):
  File "/home/airflow/.local/lib/python3.7/site-packages/airflow/operators/python.py", line 171, in execute
    return_value = self.execute_callable()
  File "/home/airflow/.local/lib/python3.7/site-packages/airflow/operators/python.py", line 189, in execute_callable
    return self.python_callable(*self.op_args, **self.op_kwargs)
TypeError: sum_column_and_diff() missing 1 required positional argument: 'path'
[2022-12-11 14:20:01,532] {taskinstance.py:1400} INFO - Marking task as FAILED. dag_id=first_dag, task_id=sum_column_task, execution_date=20221211T141900, start_date=20221211T142000, end_date=20221211T142001
[2022-12-11 14:20:01,559] {standard_task_runner.py:97} ERROR - Failed to execute job 418 for task sum_column_task (sum_column_and_diff() missing 1 required positional argument: 'path'; 571)
[2022-12-11 14:20:01,593] {local_task_job.py:156} INFO - Task exited with return code 1
[2022-12-11 14:20:01,663] {local_task_job.py:273} INFO - 0 downstream tasks scheduled from follow-on schedule check
