[2022-12-04 15:57:28,942] {taskinstance.py:1159} INFO - Dependencies all met for <TaskInstance: first_dag.hel1o scheduled__2022-01-15T00:00:00+00:00 [queued]>
[2022-12-04 15:57:29,031] {taskinstance.py:1159} INFO - Dependencies all met for <TaskInstance: first_dag.hel1o scheduled__2022-01-15T00:00:00+00:00 [queued]>
[2022-12-04 15:57:29,033] {taskinstance.py:1356} INFO - 
--------------------------------------------------------------------------------
[2022-12-04 15:57:29,034] {taskinstance.py:1357} INFO - Starting attempt 1 of 1
[2022-12-04 15:57:29,035] {taskinstance.py:1358} INFO - 
--------------------------------------------------------------------------------
[2022-12-04 15:57:29,119] {taskinstance.py:1377} INFO - Executing <Task(BashOperator): hel1o> on 2022-01-15 00:00:00+00:00
[2022-12-04 15:57:29,126] {standard_task_runner.py:52} INFO - Started process 302 to run task
[2022-12-04 15:57:29,163] {standard_task_runner.py:79} INFO - Running: ['***', 'tasks', 'run', 'first_dag', 'hel1o', 'scheduled__2022-01-15T00:00:00+00:00', '--job-id', '18', '--raw', '--subdir', 'DAGS_FOLDER/first-dag.py', '--cfg-path', '/tmp/tmpxly556b8', '--error-file', '/tmp/tmptiss4lge']
[2022-12-04 15:57:29,166] {standard_task_runner.py:80} INFO - Job 18: Subtask hel1o
[2022-12-04 15:57:29,433] {task_command.py:369} INFO - Running <TaskInstance: first_dag.hel1o scheduled__2022-01-15T00:00:00+00:00 [running]> on host fb90b48d1471
[2022-12-04 15:57:29,790] {taskinstance.py:1571} INFO - Exporting the following env vars:
AIRFLOW_CTX_DAG_OWNER=***
AIRFLOW_CTX_DAG_ID=first_dag
AIRFLOW_CTX_TASK_ID=hel1o
AIRFLOW_CTX_EXECUTION_DATE=2022-01-15T00:00:00+00:00
AIRFLOW_CTX_TRY_NUMBER=1
AIRFLOW_CTX_DAG_RUN_ID=scheduled__2022-01-15T00:00:00+00:00
[2022-12-04 15:57:29,801] {subprocess.py:62} INFO - Tmp dir root location: 
 /tmp
[2022-12-04 15:57:29,804] {subprocess.py:74} INFO - Running command: ['bash', '-c', 'echohe11o']
[2022-12-04 15:57:29,826] {subprocess.py:85} INFO - Output:
[2022-12-04 15:57:29,832] {subprocess.py:92} INFO - bash: line 1: echohe11o: command not found
[2022-12-04 15:57:29,834] {subprocess.py:96} INFO - Command exited with return code 127
[2022-12-04 15:57:29,936] {taskinstance.py:1889} ERROR - Task failed with exception
Traceback (most recent call last):
  File "/home/airflow/.local/lib/python3.7/site-packages/airflow/operators/bash.py", line 195, in execute
    f'Bash command failed. The command returned a non-zero exit code {result.exit_code}.'
airflow.exceptions.AirflowException: Bash command failed. The command returned a non-zero exit code 127.
[2022-12-04 15:57:29,995] {taskinstance.py:1400} INFO - Marking task as FAILED. dag_id=first_dag, task_id=hel1o, execution_date=20220115T000000, start_date=20221204T155728, end_date=20221204T155729
[2022-12-04 15:57:30,140] {standard_task_runner.py:97} ERROR - Failed to execute job 18 for task hel1o (Bash command failed. The command returned a non-zero exit code 127.; 302)
[2022-12-04 15:57:30,218] {local_task_job.py:156} INFO - Task exited with return code 1
[2022-12-04 15:57:30,297] {local_task_job.py:273} INFO - 0 downstream tasks scheduled from follow-on schedule check
