[2022-12-11 14:29:04,372] {taskinstance.py:1159} INFO - Dependencies all met for <TaskInstance: first_dag.sum_column_task scheduled__2022-12-11T14:28:00+00:00 [queued]>
[2022-12-11 14:29:04,390] {taskinstance.py:1159} INFO - Dependencies all met for <TaskInstance: first_dag.sum_column_task scheduled__2022-12-11T14:28:00+00:00 [queued]>
[2022-12-11 14:29:04,392] {taskinstance.py:1356} INFO - 
--------------------------------------------------------------------------------
[2022-12-11 14:29:04,393] {taskinstance.py:1357} INFO - Starting attempt 1 of 1
[2022-12-11 14:29:04,399] {taskinstance.py:1358} INFO - 
--------------------------------------------------------------------------------
[2022-12-11 14:29:04,421] {taskinstance.py:1377} INFO - Executing <Task(PythonOperator): sum_column_task> on 2022-12-11 14:28:00+00:00
[2022-12-11 14:29:04,430] {standard_task_runner.py:52} INFO - Started process 766 to run task
[2022-12-11 14:29:04,438] {standard_task_runner.py:79} INFO - Running: ['***', 'tasks', 'run', 'first_dag', 'sum_column_task', 'scheduled__2022-12-11T14:28:00+00:00', '--job-id', '466', '--raw', '--subdir', 'DAGS_FOLDER/first-dag.py', '--cfg-path', '/tmp/tmprr5f__ne', '--error-file', '/tmp/tmpx54ocvgx']
[2022-12-11 14:29:04,440] {standard_task_runner.py:80} INFO - Job 466: Subtask sum_column_task
[2022-12-11 14:29:04,524] {task_command.py:369} INFO - Running <TaskInstance: first_dag.sum_column_task scheduled__2022-12-11T14:28:00+00:00 [running]> on host 7e39590a7807
[2022-12-11 14:29:04,633] {taskinstance.py:1571} INFO - Exporting the following env vars:
AIRFLOW_CTX_DAG_OWNER=***
AIRFLOW_CTX_DAG_ID=first_dag
AIRFLOW_CTX_TASK_ID=sum_column_task
AIRFLOW_CTX_EXECUTION_DATE=2022-12-11T14:28:00+00:00
AIRFLOW_CTX_TRY_NUMBER=1
AIRFLOW_CTX_DAG_RUN_ID=scheduled__2022-12-11T14:28:00+00:00
[2022-12-11 14:29:04,651] {taskinstance.py:1889} ERROR - Task failed with exception
Traceback (most recent call last):
  File "/home/airflow/.local/lib/python3.7/site-packages/airflow/operators/python.py", line 171, in execute
    return_value = self.execute_callable()
  File "/home/airflow/.local/lib/python3.7/site-packages/airflow/operators/python.py", line 189, in execute_callable
    return self.python_callable(*self.op_args, **self.op_kwargs)
  File "/opt/airflow/dags/first-dag.py", line 31, in sum_column_and_diff
    sum_columns = reduce(lambda a, b: (a[0] + b[0], a[1] + b[1]), prepare_lines)
  File "/opt/airflow/dags/first-dag.py", line 29, in <lambda>
    (int(x[0]), int(x[1].replace("\n", ""))),
ValueError: invalid literal for int() with base 10: 'None779'
[2022-12-11 14:29:04,666] {taskinstance.py:1400} INFO - Marking task as FAILED. dag_id=first_dag, task_id=sum_column_task, execution_date=20221211T142800, start_date=20221211T142904, end_date=20221211T142904
[2022-12-11 14:29:04,680] {standard_task_runner.py:97} ERROR - Failed to execute job 466 for task sum_column_task (invalid literal for int() with base 10: 'None779'; 766)
[2022-12-11 14:29:04,731] {local_task_job.py:156} INFO - Task exited with return code 1
[2022-12-11 14:29:04,809] {local_task_job.py:273} INFO - 0 downstream tasks scheduled from follow-on schedule check
